<mujoco model="d1h">
  <default>
    <default class="robot">
      <default class="visual">
        <geom contype="0" conaffinity="0" group="2" />
      </default>
      <default class="collision">
        <geom contype="0" conaffinity="1" group="3" />
      </default>
    </default>
  </default>

  <compiler angle="radian" meshdir="assets" balanceinertia="true" />

  <worldbody>
    <body name="base_link" childclass="robot" pos="0 0 0.5927">
      <geom name="base_link_visual" type="box" size="0.0005 0.0005 0.0005" material="default_material" class="visual" />
      <site name="imu" pos="0 0 0" />
      <body name="imu_link">
        <inertial pos="0 0 0" mass="0.001" diaginertia="0.0001 0.0001 0.0001" />
        <geom name="imu_link_collision" type="box" size="0.0005 0.0005 0.0005" class="collision" />
        <geom name="imu_link_visual" type="box" size="0.0005 0.0005 0.0005" material="default_material" class="visual" />
      </body>
      <body name="F_base_link">
        <inertial pos="0.04005271 0.00019692 -0.02084955" mass="8.44614222" diaginertia="0.07256618 0.11587953 0.11697399" />
        <geom name="F_base_link_collision_0" type="box" size="0.1375 0.075 0.0875" class="collision" />
        <geom name="F_base_link_collision_1" pos="0 0 -0.12" type="box" size="0.155 0.06 0.03" class="collision" />
        <geom name="F_base_link_visual" type="mesh" mesh="F_base_link_base_link" material="default_material" class="visual" />
        <body name="F_funtion_link" pos="0.1545 0 0">
          <inertial pos="0.01321944 0.0 0.00563897" mass="0.67772" diaginertia="0.0046602 0.0017478 0.0031524" />
          <geom name="F_funtion_link_collision" pos="0.008 0 0" type="box" size="0.02475 0.075 0.0875" class="collision" />
          <geom name="F_funtion_link_visual" type="mesh" mesh="F_funtion_link_funtion_Link" material="default_material" class="visual" />
        </body>
        <body name="F_docking_link" pos="-0.187 0 0">
          <inertial pos="0.01527894 0.00855247 0.00284739" mass="2.20153411" diaginertia="0.01876158 0.00631988 0.01358894" />
          <geom name="F_docking_link_collision" pos="0.0065 0 0" type="box" size="0.04255 0.075 0.0875" class="collision" />
          <geom name="F_docking_link_visual" type="mesh" mesh="F_docking_link_docking_Link" material="default_material" class="visual" />
        </body>
        <body name="FL_hip" pos="0.0945 0.0775 0" quat="0.5 0.5 0.5 0.5">
          <inertial pos="-0.01814352 -7.96e-06 -0.09365134" mass="1.69464273" diaginertia="0.00379266 0.00276068 0.00214485" />
          <joint name="FL_hip_joint" type="hinge" range="-0.7853981633974483 0.7853981633974483" axis="0 0 1" />
          <geom name="FL_hip_visual" type="mesh" mesh="FL_hip_L_hip" material="default_material" class="visual" />
          <body name="FL_thigh" pos="0.0905 0 -0.0945" quat="0.5001 -0.5001 0.4999 -0.4999">
            <inertial pos="0.02895091 0.00356333 -0.02811556" mass="2.55232244" diaginertia="0.00426053 0.01734276 0.01796394" />
            <joint name="FL_thigh_joint" type="hinge" range="-1.8325957145940461 3.4033920413889422" axis="0 0 1" />
            <geom name="FL_thigh_collision" pos="0.06 0.02 0" quat="0.9914 0 0 0.1305" type="box" size="0.13 0.045 0.025" class="collision" />
            <geom name="FL_thigh_visual" type="mesh" mesh="FL_thigh_L_thigh" material="default_material" class="visual" />
            <body name="FL_calf" pos="0.25 0 0">
              <inertial pos="0.12506267 0.00606587 0.00312587" mass="0.46345045" diaginertia="0.00023821 0.00488539 0.00493944" />
              <joint name="FL_calf_joint" type="hinge" range="-2.775 -0.855" axis="0 0 1" />
              <geom name="FL_calf_collision" pos="0.15 0.01 0" quat="0.9992 0 0 -0.04" type="box" size="0.12 0.02 0.025" class="collision" />
              <geom name="FL_calf_visual" type="mesh" mesh="FL_calf_L_calf" material="default_material" class="visual" />
              <body name="FL_foot" pos="0.25 0 0.052166">
                <inertial pos="-2.82e-06 0.0 -0.00091845" mass="1.6631" diaginertia="0.00397025 0.00395149 0.00760863" />
                <joint name="FL_foot_joint" type="hinge" range="-1000000.0 1000000.0" axis="0 0 1" />
                <geom name="FL_foot_collision" type="cylinder" size="0.087 0.02" class="collision" />
                <geom name="FL_foot_visual" type="mesh" mesh="FL_foot_L_foot" material="default_material" class="visual" />
              </body>
            </body>
          </body>
        </body>
        <body name="FR_hip" pos="0.0945 -0.0775 0" quat="0.5 0.5 0.5 0.5">
          <inertial pos="0.01814352 -8e-06 -0.09365134" mass="1.69464279" diaginertia="0.00379266 0.00276068 0.00214485" />
          <joint name="FR_hip_joint" type="hinge" range="-0.7853981633974483 0.7853981633974483" axis="0 0 1" />
          <geom name="FR_hip_visual" type="mesh" mesh="FR_hip_R_hip" material="default_material" class="visual" />
          <body name="FR_thigh" pos="-0.0905 0 -0.0945" quat="0.4999 -0.4999 0.5001 -0.5001">
            <inertial pos="0.0291816 0.00370278 0.02811568" mass="2.55232278" diaginertia="0.00427405 0.01729241 0.01792714" />
            <joint name="FR_thigh_joint" type="hinge" range="-1.8325957145940461 3.4033920413889422" axis="0 0 1" />
            <geom name="FR_thigh_collision" pos="0.06 0.02 0" quat="0.9914 0 0 0.1305" type="box" size="0.13 0.045 0.025" class="collision" />
            <geom name="FR_thigh_visual" type="mesh" mesh="FR_thigh_R_thigh" material="default_material" class="visual" />
            <body name="FR_calf" pos="0.25 0 0">
              <inertial pos="0.12506359 0.00606606 -0.0031258" mass="0.46345511" diaginertia="0.00023821 0.00488543 0.00493948" />
              <joint name="FR_calf_joint" type="hinge" range="-2.775 -0.855" axis="0 0 1" />
              <geom name="FR_calf_collision" pos="0.15 0.01 0" quat="0.9992 0 0 -0.04" type="box" size="0.12 0.02 0.025" class="collision" />
              <geom name="FR_calf_visual" type="mesh" mesh="FR_calf_R_calf" material="default_material" class="visual" />
              <body name="FR_foot" pos="0.25 0 -0.052166" quat="0.364 0 0 0.9314">
                <inertial pos="-2.78e-06 0.0 0.00091859" mass="1.6631" diaginertia="0.00397018 0.00395159 0.00760867" />
                <joint name="FR_foot_joint" type="hinge" range="-1000000.0 1000000.0" axis="0 0 1" />
                <geom name="FR_foot_collision" type="cylinder" size="0.087 0.02" class="collision" />
                <geom name="FR_foot_visual" type="mesh" mesh="FR_foot_R_foot" material="default_material" class="visual" />
              </body>
            </body>
          </body>
        </body>
      </body>
      <freejoint name="floating_base" />
    </body>
  </worldbody>

  <asset>
    <material name="default_material" rgba="0.7 0.7 0.7 1" />
    <mesh name="F_base_link_base_link" file="base_link.STL" />
    <mesh name="F_funtion_link_funtion_Link" file="funtion_Link.STL" />
    <mesh name="F_docking_link_docking_Link" file="docking_Link.STL" />
    <mesh name="FL_hip_L_hip" file="L_hip.STL" />
    <mesh name="FL_thigh_L_thigh" file="L_thigh.STL" />
    <mesh name="FL_calf_L_calf" file="L_calf.STL" />
    <mesh name="FL_foot_L_foot" file="L_foot.STL" />
    <mesh name="FR_hip_R_hip" file="R_hip.STL" />
    <mesh name="FR_thigh_R_thigh" file="R_thigh.STL" />
    <mesh name="FR_calf_R_calf" file="R_calf.STL" />
    <mesh name="FR_foot_R_foot" file="R_foot.STL" />
  </asset>

  <actuator>
    <motor name="FL_hip_joint" joint="FL_hip_joint" />
    <motor name="FL_thigh_joint" joint="FL_thigh_joint" />
    <motor name="FL_calf_joint" joint="FL_calf_joint" />
    <motor name="FL_foot_joint" joint="FL_foot_joint" />
    <motor name="FR_hip_joint" joint="FR_hip_joint" />
    <motor name="FR_thigh_joint" joint="FR_thigh_joint" />
    <motor name="FR_calf_joint" joint="FR_calf_joint" />
    <motor name="FR_foot_joint" joint="FR_foot_joint" />
  </actuator>

  <sensor>
    <gyro site="imu" name="gyro"/>
    <velocimeter site="imu" name="local_linvel"/>
    <framezaxis objtype="site" objname="imu" name="upvector"/>
  </sensor>

  <keyframe>
    <key name="home" qpos="
        0 0 0.50 1 0 0 0
        0.0 0.8 -1.5 0.0
        0.0 0.8 -1.5 0.0"
      ctrl="
        0.0 0.8 -1.5 0.0
        0.0 0.8 -1.5 0.0"/>
  </keyframe>
</mujoco>