<mujoco model="d1h_description">
  <compiler angle="radian" meshdir="assets" autolimits="true" />
  <option cone="elliptic" impratio="100" />
  <default>
    <default class="d1h">
      <geom friction="0.4" margin="0.001" condim="1"/>
      <joint axis="0 1 0" damping="0.1" armature="0.01" frictionloss="0.2"/>
      <default class="visual">
        <geom type="mesh" contype="0" conaffinity="0" group="2" density="0"/>
      </default>
      <default class="collision">
        <geom group="3" />
      </default>
    </default>
  </default>

  <asset>
    <mesh name="base_link" file="base_link.STL"/>
    <mesh name="funtion_Link" file="funtion_Link.STL"/>
    <mesh name="docking_Link" file="docking_Link.STL"/>
    <mesh name="L_hip" file="L_hip.STL"/>
    <mesh name="L_thigh" file="L_thigh.STL"/>
    <mesh name="L_calf" file="L_calf.STL"/>
    <mesh name="L_foot" file="L_foot.STL"/>
    <mesh name="R_hip" file="R_hip.STL"/>
    <mesh name="R_thigh" file="R_thigh.STL"/>
    <mesh name="R_calf" file="R_calf.STL"/>
    <mesh name="R_foot" file="R_foot.STL"/>
  </asset>

  <worldbody>
    <body name="base_link" pos="0 0 0.8" childclass="d1h">
      <inertial pos="0.00652471 0.00180904 -0.0146554" quat="0.00501199 0.705938 -0.0170284 0.708051" mass="11.3274" diaginertia="0.231094 0.222595 0.0974676"/>
      <site name="imu" size="0.01"/>
      <joint name="floating_base_joint" type="free" limited="false" actuatorfrclimited="false"/>
      <geom type="mesh" class="visual" rgba="0.75294 0.75294 0.75294 1" mesh="base_link"/>
      <geom size="0.1375 0.075 0.0875" type="box" class="collision" rgba="0.75294 0.75294 0.75294 1"/>
      <geom size="0.155 0.06 0.03" pos="0 0 -0.12" type="box" class="collision" rgba="0.75294 0.75294 0.75294 1"/>
      <geom pos="0.1545 0 0" quat="1 0 0 0" type="mesh" rgba="0.75294 0.75294 0.75294 1" mesh="funtion_Link"/>
      <geom size="0.02475 0.075 0.0875" pos="0.1625 0 0" type="box" class="collision" rgba="0.75294 0.75294 0.75294 1"/>
      <geom pos="-0.187 0 0" quat="1 0 0 0" type="mesh" rgba="0.75294 0.75294 0.75294 1" mesh="docking_Link"/>
      <geom size="0.04255 0.075 0.0875" pos="-0.1805 0 0" type="box" class="collision" rgba="0.75294 0.75294 0.75294 1"/>
      <body name="FL_hip" pos="0.0945 0.0775 0" quat="0.499998 0.5 0.500002 0.5">
        <inertial pos="-0.0181435 -7.96e-06 -0.0936513" quat="0.999969 0.002505 0.00743808 -9.41679e-05" mass="1.69464" diaginertia="0.00379302 0.0027607 0.00214447"/>
        <joint name="FL_hip_joint" pos="0 0 0" axis="0 0 1" range="-0.785398 0.785398" actuatorfrcrange="-80 80"/>
        <geom type="mesh" class="visual" rgba="0.75294 0.75294 0.75294 1" mesh="L_hip"/>
        <body name="FL_thigh" pos="0.0905 0 -0.0945" quat="0.500098 -0.5001 0.499902 -0.4999">
          <inertial pos="0.0289509 0.00356333 -0.0281156" quat="-0.0769104 0.652025 5.23527e-05 0.754286" mass="2.55232" diaginertia="0.0182972 0.0174693 0.00380065"/>
          <joint name="FL_thigh_joint" pos="0 0 0" axis="0 0 1" range="-1.8326 3.40339" actuatorfrcrange="-80 80"/>
          <geom type="mesh" class="visual" rgba="0.75294 0.75294 0.75294 1" mesh="L_thigh"/>
          <geom size="0.13 0.045 0.025" pos="0.06 0.02 0" quat="0.991445 0 0 0.130526" type="box" class="collision" rgba="0.75294 0.75294 0.75294 1"/>
          <body name="FL_calf" pos="0.25 0 0">
            <inertial pos="0.125063 0.00606587 0.00312587" quat="-0.0425827 0.690156 -0.0920102 0.716523" mass="0.46345" diaginertia="0.00494513 0.00490922 0.000208685"/>
            <joint name="FL_calf_joint" pos="0 0 0" axis="0 0 1" range="-2.775 -0.855" actuatorfrcrange="-80 80"/>
            <geom type="mesh" class="visual" rgba="0.75294 0.75294 0.75294 1" mesh="L_calf"/>
            <geom size="0.12 0.02 0.025" pos="0.15 0.01 0" quat="0.9992 0 0 -0.0399893" type="box" class="collision" rgba="0.75294 0.75294 0.75294 1"/>
            <body name="FL_foot" pos="0.25 0 0.052166">
              <inertial pos="-2.82e-06 0 -0.00091845" quat="0.334356 0.623085 -0.334302 0.623067" mass="1.6631" diaginertia="0.00760863 0.00398501 0.00393673"/>
              <joint name="FL_foot_joint" pos="0 0 0" axis="0 0 1" range="-1000000 1000000" actuatorfrcrange="-12 12"/>
              <geom type="mesh" class="visual" rgba="0.698039 0.698039 0.698039 1" mesh="L_foot"/>
              <geom size="0.087 0.02" type="cylinder" class="collision" rgba="0.698039 0.698039 0.698039 1"/>
            </body>
          </body>
        </body>
      </body>
      <body name="FR_hip" pos="0.0945 -0.0775 0" quat="0.499998 0.5 0.500002 0.5">
        <inertial pos="0.0181435 -8e-06 -0.0936513" quat="0.999969 0.002505 -0.00743808 9.41679e-05" mass="1.69464" diaginertia="0.00379302 0.0027607 0.00214447"/>
        <joint name="FR_hip_joint" pos="0 0 0" axis="0 0 1" range="-0.785398 0.785398" actuatorfrcrange="-80 80"/>
        <geom type="mesh" class="visual" rgba="0.75294 0.75294 0.75294 1" mesh="R_hip"/>
        <body name="FR_thigh" pos="-0.0905 0 -0.0945" quat="0.499898 -0.4999 0.500102 -0.5001">
          <inertial pos="0.0291816 0.00370278 0.0281157" quat="0.00133055 0.754556 0.0787582 0.651491" mass="2.55232" diaginertia="0.0182666 0.0174178 0.0038092"/>
          <joint name="FR_thigh_joint" pos="0 0 0" axis="0 0 1" range="-1.8326 3.40339" actuatorfrcrange="-80 80"/>
          <geom type="mesh" class="visual" rgba="0.752941 0.752941 0.752941 1" mesh="R_thigh"/>
          <geom size="0.13 0.045 0.025" pos="0.06 0.02 0" quat="0.991445 0 0 0.130526" type="box" class="collision" rgba="0.752941 0.752941 0.752941 1"/>
          <body name="FR_calf" pos="0.25 0 0">
            <inertial pos="0.125064 0.00606606 -0.0031258" quat="0.0919975 0.716523 0.0425713 0.690159" mass="0.463455" diaginertia="0.00494517 0.00490926 0.000208687"/>
            <joint name="FR_calf_joint" pos="0 0 0" axis="0 0 1" range="-2.775 -0.855" actuatorfrcrange="-80 80"/>
            <geom type="mesh" class="visual" rgba="0.752941 0.752941 0.752941 1" mesh="R_calf"/>
            <geom size="0.12 0.02 0.025" pos="0.15 0.01 0" quat="0.9992 0 0 -0.0399893" type="box" class="collision" rgba="0.752941 0.752941 0.752941 1"/>
            <body name="FR_foot" pos="0.25 0 -0.052166" quat="0.363988 0 0 0.931404">
              <inertial pos="-2.78e-06 0 0.00091859" quat="0.333846 0.623312 -0.3339 0.62333" mass="1.6631" diaginertia="0.00760867 0.00398497 0.0039368"/>
              <joint name="FR_foot_joint" pos="0 0 0" axis="0 0 1" range="-1000000 1000000" actuatorfrcrange="-12 12"/>
              <geom type="mesh" class="visual" rgba="1 1 1 1" mesh="R_foot"/>
              <geom size="0.087 0.02" type="cylinder" class="collision" rgba="1 1 1 1"/>
            </body>
          </body>
        </body>
      </body>
    </body>
  </worldbody>

  <actuator>
    <motor name="FL_hip" joint="FL_hip_joint" ctrlrange="-80 80" />
    <motor name="FL_thigh" joint="FL_thigh_joint" ctrlrange="-80 80" />
    <motor name="FL_calf" joint="FL_calf_joint" ctrlrange="-80 80" />
    <motor name="FL_foot" joint="FL_foot_joint" ctrlrange="-12 12" />

    <motor name="FR_hip" joint="FR_hip_joint" ctrlrange="-80 80" />
    <motor name="FR_thigh" joint="FR_thigh_joint" ctrlrange="-80 80" />
    <motor name="FR_calf" joint="FR_calf_joint" ctrlrange="-80 80" />
    <motor name="FR_foot" joint="FR_foot_joint" ctrlrange="-12 12" />
  </actuator>
  <sensor>
    <jointpos name="FL_hip_pos" joint="FL_hip_joint" />
    <jointpos name="FL_thigh_pos" joint="FL_thigh_joint" />
    <jointpos name="FL_calf_pos" joint="FL_calf_joint" />
    <jointpos name="FL_foot_pos" joint="FL_foot_joint" />

    <jointpos name="FR_hip_pos" joint="FR_hip_joint" />
    <jointpos name="FR_thigh_pos" joint="FR_thigh_joint" />
    <jointpos name="FR_calf_pos" joint="FR_calf_joint" />
    <jointpos name="FR_foot_pos" joint="FR_foot_joint" />

    <jointvel name="FL_hip_vel" joint="FL_hip_joint" />
    <jointvel name="FL_thigh_vel" joint="FL_thigh_joint" />
    <jointvel name="FL_calf_vel" joint="FL_calf_joint" />
    <jointvel name="FL_foot_vel" joint="FL_foot_joint" />

    <jointvel name="FR_hip_vel" joint="FR_hip_joint" />
    <jointvel name="FR_thigh_vel" joint="FR_thigh_joint" />
    <jointvel name="FR_calf_vel" joint="FR_calf_joint" />
    <jointvel name="FR_foot_vel" joint="FR_foot_joint" />

    <jointactuatorfrc name="FL_hip_torque" joint="FL_hip_joint" noise="0.01" />
    <jointactuatorfrc name="FL_thigh_torque" joint="FL_thigh_joint" noise="0.01" />
    <jointactuatorfrc name="FL_calf_torque" joint="FL_calf_joint" noise="0.01" />
    <jointactuatorfrc name="FL_foot_torque" joint="FL_foot_joint" noise="0.01" />

    <jointactuatorfrc name="FR_hip_torque" joint="FR_hip_joint" noise="0.01" />
    <jointactuatorfrc name="FR_thigh_torque" joint="FR_thigh_joint" noise="0.01" />
    <jointactuatorfrc name="FR_calf_torque" joint="FR_calf_joint" noise="0.01" />
    <jointactuatorfrc name="FR_foot_torque" joint="FR_foot_joint" noise="0.01" />

    <framezaxis name="upvector" objtype="site" objname="imu" />
    <gyro name="gyro" site="imu" />
    <accelerometer name="trunk_accel" site="imu" />

    <framepos name="frame_pos" objtype="site" objname="imu" />
    <framelinvel name="local_linvel" objtype="site" objname="imu" />
  </sensor>

  <keyframe>
    <key name="home" qpos="0 0 0.8 1 0 0 0  0.1 0.8 -1.5 0  -0.1 0.8 -1.5 0" />
  </keyframe>
</mujoco>